<?xml version="1.0"?>
<robot xmlns:xacro="http://www.ros.org/wiki/xacro" name="my_rover">

  <xacro:property name="chassis_length" value="0.5"/>
  <xacro:property name="chassis_width" value="0.3"/>
  <link name="dummy_root"/>

  <joint name="dummy_joint" type="fixed">
    <parent link="dummy_root"/>
    <child link="base_link"/>
  </joint>


  <link name="base_link">
    <visual>
      <geometry><box size="${chassis_length} ${chassis_width} 0.1"/></geometry>
      <material name="blue"><color rgba="0 0 1 1"/></material>
    </visual>
    <collision>
      <geometry><box size="${chassis_length} ${chassis_width} 0.1"/></geometry>
    </collision>
    <inertial>
      <mass value="5.0"/>
      <inertia ixx="0.1" ixy="0.0" ixz="0.0" iyy="0.1" iyz="0.0" izz="0.1"/>
    </inertial>
  </link>


  <xacro:macro name="wheel" params="prefix x_reflect y_reflect">
    
    <link name="${prefix}_wheel">
      <visual>
        <geometry><cylinder radius="0.1" length="0.05"/></geometry>
        <material name="black"><color rgba="0 0 0 1"/></material>
      </visual>
      <collision>
        <geometry><cylinder radius="0.1" length="0.05"/></geometry>
      </collision>
      <inertial>
        <mass value="1.0"/>
        <inertia ixx="0.01" ixy="0.0" ixz="0.0" iyy="0.01" iyz="0.0" izz="0.01"/> 
      </inertial>
    </link>

    <joint name="${prefix}_wheel_joint" type="continuous">
      <parent link="base_link"/>
      <child link="${prefix}_wheel"/>
      <origin xyz="${x_reflect*0.2} ${y_reflect*0.175} 0" rpy="1.57 0 0"/>
      <axis xyz="0 0 1"/>
    </joint>

  </xacro:macro>


  <xacro:wheel prefix="front_left" x_reflect="1" y_reflect="1" />
  <xacro:wheel prefix="front_right" x_reflect="1" y_reflect="-1" />
  <xacro:wheel prefix="rear_left" x_reflect="-1" y_reflect="1" />
  <xacro:wheel prefix="rear_right" x_reflect="-1" y_reflect="-1" />

</robot>
