<?xml version="1.0"?>
<robot xmlns:xacro="http://www.ros.org/wiki/xacro" name="my_rover">

  <xacro:property name="chassis_length" value="0.5"/>
  <xacro:property name="chassis_width" value="0.3"/>
  <link name="dummy_root"/>

  <joint name="dummy_joint" type="fixed">
    <parent link="dummy_root"/>
    <child link="base_link"/>
  </joint>


  <link name="base_link">
    <visual>
      <geometry><box size="${chassis_length} ${chassis_width} 0.1"/></geometry>
      <material name="blue"><color rgba="0 0 1 1"/></material>
    </visual>
    <collision>
      <geometry><box size="${chassis_length} ${chassis_width} 0.1"/></geometry>
    </collision>
    <inertial>
      <mass value="5.0"/>
      <inertia ixx="0.1" ixy="0.0" ixz="0.0" iyy="0.1" iyz="0.0" izz="0.1"/>
    </inertial>
  </link>


<xacro:macro name="wheel" params="prefix x_reflect y_reflect">
    
    <link name="${prefix}_wheel">
      <visual>
        <geometry><cylinder radius="0.1" length="0.05"/></geometry>
        <material name="black"><color rgba="0 0 0 1"/></material>
      </visual>
      
      <collision>
        <geometry><sphere radius="0.1"/></geometry>
      </collision>
      
      <inertial>
        <mass value="1.0"/>
        <inertia ixx="0.01" ixy="0.0" ixz="0.0" iyy="0.01" iyz="0.0" izz="0.01"/> 
      </inertial>
    </link>

    <joint name="${prefix}_wheel_joint" type="continuous">
      <parent link="base_link"/>
      <child link="${prefix}_wheel"/>
      <origin xyz="${x_reflect*0.2} ${y_reflect*0.175} 0" rpy="1.57 0 0"/>
      <axis xyz="0 0 1"/>
    </joint>

    <gazebo reference="${prefix}_wheel">
      <mu1>1.0</mu1>   
      <mu2>0.01</mu2>  
    </gazebo>

  </xacro:macro>

  <xacro:wheel prefix="front_left" x_reflect="1" y_reflect="1" />
  <xacro:wheel prefix="front_right" x_reflect="1" y_reflect="-1" />
  <xacro:wheel prefix="rear_left" x_reflect="-1" y_reflect="1" />
  <xacro:wheel prefix="rear_right" x_reflect="-1" y_reflect="-1" />
  
  <link name="camera_link">
    <visual>
      <geometry><box size="0.02 0.05 0.03"/></geometry>
      <material name="black"><color rgba="0 0 0 1"/></material>
    </visual>
    <inertial>
      <mass value="0.1"/>
      <inertia ixx="0.01" ixy="0" ixz="0" iyy="0.01" iyz="0" izz="0.01"/>
    </inertial>
  </link>
  
<joint name="camera_joint" type="fixed">
  <parent link="base_link"/>
  <child link="camera_link"/>
  <origin xyz="0.25 0 0.05" rpy="0 0 0"/> 
</joint>

  <link name="camera_optical_link"/>
  
  <joint name="camera_optical_joint" type="fixed">
    <parent link="camera_link"/>
    <child link="camera_optical_link"/>
    <origin xyz="0 0 0" rpy="-1.57 0 -1.57"/> 
  </joint>

  <link name="lidar_link">
    <visual>
      <geometry><cylinder radius="0.05" length="0.04"/></geometry>
      <material name="black"><color rgba="0 0 0 1"/></material>
    </visual>
    <inertial>
      <mass value="0.1"/>
      <inertia ixx="0.01" ixy="0" ixz="0" iyy="0.01" iyz="0" izz="0.01"/>
    </inertial>
  </link>

  <joint name="lidar_joint" type="fixed">
    <parent link="base_link"/>
    <child link="lidar_link"/>
    <origin xyz="0 0 0.07" rpy="0 0 0"/> 
  </joint>

  <link name="imu_link"/> <joint name="imu_joint" type="fixed">
    <parent link="base_link"/>
    <child link="imu_link"/>
    <origin xyz="0 0 0" rpy="0 0 0"/> 
  </joint>
  
  <gazebo reference="camera_link">
    <sensor type="camera" name="rover_camera">
      <always_on>1</always_on>
      <topic>/camera/image_raw</topic>
      <update_rate>30.0</update_rate>
      <visualize>true</visualize>
      <camera name="head">
        <horizontal_fov>1.3962634</horizontal_fov>
        <image>
          <width>800</width>
          <height>800</height>
          <format>R8G8B8</format>
        </image>
        <clip>
          <near>0.02</near>
          <far>300</far>
        </clip>
      </camera>
    </sensor>
  </gazebo>

  <gazebo reference="lidar_link">
    <sensor type="gpu_lidar" name="rover_lidar">
      <always_on>1</always_on>
      <topic>/scan</topic>
      <ignition_frame_id>lidar_link</ignition_frame_id>
      <update_rate>10.0</update_rate>
      <visualize>true</visualize>
      <ray>
        <scan>
          <horizontal>
            <samples>640</samples>
            <resolution>1</resolution>
            <min_angle>-3.14159</min_angle>
            <max_angle>3.14159</max_angle>
          </horizontal>
        </scan>
        <range>
          <min>0.08</min>
          <max>12.0</max>
        </range>
      </ray>
    </sensor>
  </gazebo>

  <gazebo reference="imu_link">
    <sensor type="imu" name="rover_imu">
      <always_on>1</always_on>
      <topic>/imu/data</topic>
      <update_rate>100.0</update_rate>
      <visualize>true</visualize>
    </sensor>
  </gazebo>
  
  <gazebo>
    <plugin filename="libignition-gazebo-diff-drive-system.so" name="ignition::gazebo::systems::DiffDrive">
      <left_joint>front_left_wheel_joint</left_joint>
      <left_joint>rear_left_wheel_joint</left_joint>
      <right_joint>front_right_wheel_joint</right_joint>
      <right_joint>rear_right_wheel_joint</right_joint>

      <wheel_separation>0.35</wheel_separation>
      <wheel_radius>0.1</wheel_radius>

      <topic>cmd_vel</topic>
      <publish_odom>true</publish_odom>
      <publish_odom_tf>true</publish_odom_tf>
      <odom_publish_frequency>50</odom_publish_frequency>
      <frame_id>odom</frame_id>
      <child_frame_id>base_link</child_frame_id>
    </plugin>
  </gazebo>

  <gazebo>
    <plugin filename="libignition-gazebo-joint-state-publisher-system.so"
            name="ignition::gazebo::systems::JointStatePublisher">
    </plugin>
  </gazebo>

</robot>
