<?xml version="1.0"?>
<robot xmlns:xacro="http://www.ros.org/wiki/xacro" name="my_rover">

  <xacro:property name="chassis_length" value="0.5"/>
  <xacro:property name="chassis_width" value="0.3"/>
  <link name="dummy_root"/>

  <joint name="dummy_joint" type="fixed">
    <parent link="dummy_root"/>
    <child link="base_link"/>
  </joint>


  <link name="base_link">
    <visual>
      <geometry><box size="${chassis_length} ${chassis_width} 0.1"/></geometry>
      <material name="blue"><color rgba="0 0 1 1"/></material>
    </visual>
    <collision>
      <geometry><box size="${chassis_length} ${chassis_width} 0.1"/></geometry>
    </collision>
    <inertial>
      <mass value="5.0"/>
      <inertia ixx="0.1" ixy="0.0" ixz="0.0" iyy="0.1" iyz="0.0" izz="0.1"/>
    </inertial>
  </link>


  <xacro:macro name="wheel" params="prefix x_reflect y_reflect">
    
    <link name="${prefix}_wheel">
      <visual>
        <geometry><cylinder radius="0.1" length="0.05"/></geometry>
        <material name="black"><color rgba="0 0 0 1"/></material>
      </visual>
      <collision>
        <geometry><cylinder radius="0.1" length="0.05"/></geometry>
      </collision>
      <inertial>
        <mass value="1.0"/>
        <inertia ixx="0.01" ixy="0.0" ixz="0.0" iyy="0.01" iyz="0.0" izz="0.01"/> 
      </inertial>
    </link>

    <joint name="${prefix}_wheel_joint" type="continuous">
      <parent link="base_link"/>
      <child link="${prefix}_wheel"/>
      <origin xyz="${x_reflect*0.2} ${y_reflect*0.175} 0" rpy="1.57 0 0"/>
      <axis xyz="0 0 1"/>
    </joint>

  </xacro:macro>


  <xacro:wheel prefix="front_left" x_reflect="1" y_reflect="1" />
  <xacro:wheel prefix="front_right" x_reflect="1" y_reflect="-1" />
  <xacro:wheel prefix="rear_left" x_reflect="-1" y_reflect="1" />
  <xacro:wheel prefix="rear_right" x_reflect="-1" y_reflect="-1" />
  
  <link name="arm_link">
    <visual>
      <origin xyz="0 0 0.15" rpy="0 0 0"/>
      <geometry><cylinder radius="0.02" length="0.3"/></geometry>
      <material name="grey"><color rgba="0.5 0.5 0.5 1"/></material>
    </visual>
    <collision>
      <origin xyz="0 0 0.15" rpy="0 0 0"/>
      <geometry><cylinder radius="0.02" length="0.3"/></geometry>
    </collision>
    <inertial>
      <origin xyz="0 0 0.15" rpy="0 0 0"/>
      <mass value="0.5"/>
      <inertia ixx="0.001" ixy="0.0" ixz="0.0" iyy="0.001" iyz="0.0" izz="0.001"/>
    </inertial>
  </link>

  <joint name="arm_joint" type="revolute">
    <parent link="base_link"/>
    <child link="arm_link"/>
    <origin xyz="0.2 0 0.05" rpy="0 0 0"/>
    <axis xyz="0 1 0"/>
    <limit lower="-1.57" upper="1.57" effort="10.0" velocity="1.0"/>
    <dynamics damping="1.0" friction="0.5"/> 
  </joint>
  
  <link name="camera_link">
    <visual>
      <geometry><box size="0.02 0.05 0.03"/></geometry>
      <material name="black"><color rgba="0 0 0 1"/></material>
    </visual>
    <inertial>
      <mass value="0.1"/>
      <inertia ixx="0.01" ixy="0" ixz="0" iyy="0.01" iyz="0" izz="0.01"/>
    </inertial>
  </link>

  <joint name="camera_joint" type="fixed">
    <parent link="arm_link"/>
    <child link="camera_link"/>
    <origin xyz="0.02 0 0.3" rpy="0 0 0"/> 
  </joint>

  <link name="camera_optical_link"/>
  
  <joint name="camera_optical_joint" type="fixed">
    <parent link="camera_link"/>
    <child link="camera_optical_link"/>
    <origin xyz="0 0 0" rpy="-1.57 0 -1.57"/> 
  </joint>

  <link name="lidar_link">
    <visual>
      <geometry><cylinder radius="0.05" length="0.04"/></geometry>
      <material name="black"><color rgba="0 0 0 1"/></material>
    </visual>
    <inertial>
      <mass value="0.1"/>
      <inertia ixx="0.01" ixy="0" ixz="0" iyy="0.01" iyz="0" izz="0.01"/>
    </inertial>
  </link>

  <joint name="lidar_joint" type="fixed">
    <parent link="base_link"/>
    <child link="lidar_link"/>
    <origin xyz="0 0 0.07" rpy="0 0 0"/> 
  </joint>

  <link name="imu_link"/> <joint name="imu_joint" type="fixed">
    <parent link="base_link"/>
    <child link="imu_link"/>
    <origin xyz="0 0 0" rpy="0 0 0"/> 
  </joint>
  
  <gazebo reference="camera_link">
    <sensor type="camera" name="rover_camera">
      <always_on>1</always_on>
      <topic>/camera/image_raw</topic>
      <update_rate>30.0</update_rate>
      <visualize>true</visualize>
      <camera name="head">
        <horizontal_fov>1.3962634</horizontal_fov>
        <image>
          <width>800</width>
          <height>800</height>
          <format>R8G8B8</format>
        </image>
        <clip>
          <near>0.02</near>
          <far>300</far>
        </clip>
      </camera>
    </sensor>
  </gazebo>

  <gazebo reference="lidar_link">
    <sensor type="gpu_lidar" name="rover_lidar">
      <always_on>1</always_on>
      <topic>/scan</topic>
      <ignition_frame_id>lidar_link</ignition_frame_id>
      <update_rate>10.0</update_rate>
      <visualize>true</visualize>
      <ray>
        <scan>
          <horizontal>
            <samples>640</samples>
            <resolution>1</resolution>
            <min_angle>-3.14159</min_angle>
            <max_angle>3.14159</max_angle>
          </horizontal>
        </scan>
        <range>
          <min>0.08</min>
          <max>12.0</max>
        </range>
      </ray>
    </sensor>
  </gazebo>

  <gazebo reference="imu_link">
    <sensor type="imu" name="rover_imu">
      <always_on>1</always_on>
      <topic>/imu/data</topic>
      <update_rate>100.0</update_rate>
      <visualize>true</visualize>
    </sensor>
  </gazebo>
  
  <ros2_control name="IgnitionSystem" type="system">
    <hardware>
      <plugin>ign_ros2_control/IgnitionSystem</plugin>
    </hardware>
    
    <joint name="arm_joint">
      <command_interface name="position"/>
      <state_interface name="position"/>
      <state_interface name="velocity"/>
    </joint>

    <joint name="front_left_wheel_joint">
      <state_interface name="position"/>
      <state_interface name="velocity"/>
    </joint>
    <joint name="front_right_wheel_joint">
      <state_interface name="position"/>
      <state_interface name="velocity"/>
    </joint>
    <joint name="rear_left_wheel_joint">
      <state_interface name="position"/>
      <state_interface name="velocity"/>
    </joint>
    <joint name="rear_right_wheel_joint">
      <state_interface name="position"/>
      <state_interface name="velocity"/>
    </joint>
  </ros2_control>

  <gazebo>
    <plugin filename="libign_ros2_control-system.so" name="ign_ros2_control::IgnitionROS2ControlPlugin">
      <parameters>$(find my_robot_package)/config/ros2_controllers.yaml</parameters>
    </plugin>
  </gazebo>

  <gazebo>
    <plugin filename="libignition-gazebo-joint-state-publisher-system.so"
            name="ignition::gazebo::systems::JointStatePublisher">
    </plugin>
  </gazebo>

</robot>
